Workbook

Sheet Ponderaciones
A1: Variable | B1: Range Name | C1: Value | D1: Limit | G1: Variable | H1: Range Name | I1: Value | J1: Límite Inferior | K1: Límite Superior
A2: Ratio_Salary_EMI | B2: Income Lower | C2: 0 | D2: 0
A3: Ratio_Salary_EMI | B3: Income Middle | C3: 0 | D3: 2
A4: Ratio_Salary_EMI | B4: Income Upper | C4: 0 | D4: 2.85
A5: Delay_from_due_date | B5: delay 1 | C5: 20 | D5: 0 | G5: Delay_from_due_date | H5: delay 1 | I5: 20 | J5: 0 | K5: =J6-0.01 -> 4.49
A6: Delay_from_due_date | B6: delay 2 | C6: 10 | D6: 4.5 | G6: Delay_from_due_date | H6: delay 2 | I6: 10 | J6: 4.5 | K6: =J7-0.01 -> 6.99
A7: Delay_from_due_date | B7: delay 3 | C7: 5 | D7: 7 | G7: Delay_from_due_date | H7: delay 3 | I7: 5 | J7: 7 | K7: =J8-0.01 -> 14.99
A8: Delay_from_due_date | B8: delay 4 | C8: 0 | D8: 15 | G8: Delay_from_due_date | H8: delay 4 | I8: 0 | J8: 15 | K8: =J9-0.01 -> 19.99
A9: Delay_from_due_date | B9: delay 5 | C9: -5 | D9: 20 | G9: Delay_from_due_date | H9: delay 5 | I9: -5 | J9: 20 | K9: =J10-0.01 -> 30.99
A10: Delay_from_due_date | B10: delay 6 | C10: -10 | D10: 31 | G10: Delay_from_due_date | H10: delay 6 | I10: -10 | J10: 31 | K10: =J11-0.01 -> 40.49
A11: Delay_from_due_date | B11: delay 7 | C11: -12 | D11: 40.5 | G11: Delay_from_due_date | H11: delay 7 | I11: -12 | J11: 40.5
A12: Num_of_Delayed_Payment | B12: Low Risk | C12: 15 | D12: 0
A13: Num_of_Delayed_Payment | B13: Moderate Risk | C13: 10 | D13: 4
A14: Num_of_Delayed_Payment | C14: 5 | D14: 8
A15: Num_of_Delayed_Payment | B15: High Risk | C15: 0 | D15: 17
A16: Outstanding_Debt | B16: Low Risk | C16: 10 | D16: 0
A17: Outstanding_Debt | B17: Moderate Risk | C17: 5 | D17: 1000
A18: Outstanding_Debt | B18: High Risk | C18: -20 | D18: 2000 | G18: No Ponderado | H18: Ponderado (Approx)
A19: Credit_Utilization_Ratio | B19: Low Risk | C19: 15 | D19: 0 | F19: Punta Min | G19: =+MIN(C5:C11)+MIN(C12:C15)+MIN(C16:C18)+MIN(C19:C22)+MIN(C38:C41)+MIN(C42:C44)+MIN(C45:C48)+MIN(D56:D58)-10-10+(0.25*-12)-10-15 -> -105 | H19: =G19*1.3 -> -136.5
A20: Credit_Utilization_Ratio | B20: Moderate Risk | C20: 5 | D20: 21 | F20: Puntaje Max | G20: =+MAX(C5:C11)+MAX(C12:C15)+MAX(C16:C18)+MAX(C19:C22)+MAX(C38:C41)+MAX(C42:C44)+MAX(C45:C48)+MAX(D56:D58)+10+10+(0.5*20) -> 130 | H20: =G20*1.3 -> 169
A21: Credit_Utilization_Ratio | C21: 0 | D21: 29
A22: Credit_Utilization_Ratio | B22: High Risk | C22: -5 | D22: 60
A23: Ratio_Amount_Invested | B23: High Risk | C23: 0 | D23: 0
A24: Ratio_Amount_Invested | B24: Moderate Risk | C24: 0 | D24: 10
A25: Ratio_Amount_Invested | B25: Low Risk | C25: 0 | D25: 20
A26: Num_Credit_Card | B26: Low Risk | C26: 0 | D26: 0
A27: Num_Credit_Card | B27: Moderate Risk | C27: 0 | D27: 4
A28: Num_Credit_Card | B28: High Risk | C28: 0 | D28: 6
A29: Changed_Credit_Limit | B29: Low Risk | C29: 0 | D29: 0
A30: Changed_Credit_Limit | B30: Moderate Risk | C30: 0 | D30: 11
A31: Changed_Credit_Limit | B31: High Risk | C31: 0 | D31: 20 | E31: `
A32: Credit_Mix | B32: Low Risk | D32: Good | E32: 15
A33: Credit_Mix | B33: Moderate Risk | D33: Standard | E33: 10
A34: Credit_Mix | B34: High Risk | D34: Bad | E34: 5
A35: Credit_History_Age | B35: High Risk | C35: 0 | D35: 0
A36: Credit_History_Age | B36: Moderate Risk | C36: 0 | D36: 4
A37: Credit_History_Age | B37: Low Risk | C37: 0 | D37: 9
A38: Interest_Rate | B38: Low Risk | C38: 10 | D38: 0
A39: Interest_Rate | B39: Low Risk | C39: 5 | D39: 7
A40: Interest_Rate | B40: Moderate Risk | C40: 0 | D40: 15.5
...

Sheet Data
A1: Interest_Rate | B1: Delay_from_due_date | C1: Payment_of_Min_Amount | D1: Outstanding_Debt | E1: Num_Credit_Inquiries | F1: Num_of_Delayed_Payment | G1: Num_of_Loan | H1: Credit_Utilization_Ratio | I1: Num_Bank_Accounts | J1: Num_Credit_Card | K1: Credit_Mix | L1: Credit_History_Age | M1: Credit_Score | N1: Score Interest Rate | O1: Score Delay from due date | P1: Score Payment of Min Amount | Q1: Score Outstanding Debt | R1: Score Credit Mix | S1: Ajustment Credit History | T1: Score Credit Inquiries | U1: Score Num Delayed Payments | V1: Score Num Loan | W1: Score Credit Utilization Ratio | X1: Score Num Credit Card | Y1: Score Bank Account | Z1: Adjustment Outsanding Debt | AA1: Weigh Credit History | AB1: Class1 | AC1: Predicted Score | AD1: Credit Prediction | AE1: Credit Acceptance Prediction
A2: 19 | B2: 13 | C2: NM | D2: 0.34 | E2: 8 | F2: 20 | G2: 7 | H2: 27.100509 | I2: 8 | J2: 1 | K2: Good | L2: 16.333333 | M2: Standard | N2: =INDEX(Ponderaciones!$C$38:$D$41,MATCH(VALUE(Table32[[#This Row],[Interest_Rate]]),Ponderaciones!$D$38:$D$41,1),1) -> 0 | O2: =INDEX(Ponderaciones!$C$5:$D$11,MATCH(Table32[[#This Row],[Delay_from_due_date]],Ponderaciones!$D$5:$D$11,1),1) -> 5 | P2: =VLOOKUP(Table32[[#This Row],[Payment_of_Min_Amount]],Ponderaciones!$C$56:$D$58,2,FALSE) -> -5 | Q2: =INDEX(Ponderaciones!$C$16:$D$18,MATCH(VALUE(Table32[[#This Row],[Outstanding_Debt]]),Ponderaciones!$D$16:$D$18,1),1) -> 10 | R2: =IF(Table32[[#This Row],[Credit_Mix]]="Good",10,IF(Table32[[#This Row],[Credit_Mix]]="Standard",5,0)) -> 10 | S2: =IF(AND(Table32[[#This Row],[Credit_History_Age]]>15,Table32[[#This Row],[Interest_Rate]]<7),5,0) -> 0 | T2: =INDEX(Ponderaciones!$C$45:$D$48,MATCH(VALUE(Table32[[#This Row],[Num_Credit_Inquiries]]),Ponderaciones!$D$45:$D$48,1),1) -> 5 | U2: =INDEX(Ponderaciones!$C$12:$D$15,MATCH(VALUE(Table32[[#This Row],[Num_of_Delayed_Payment]]),Ponderaciones!$D$12:$D$15,1),1) -> 0 | V2: =INDEX(Ponderaciones!$C$42:$D$44,MATCH(VALUE(Table32[[#This Row],[Num_of_Loan]]),Ponderaciones!$D$42:$D$44,1),1) -> -5 | W2: =INDEX(Ponderaciones!$C$19:$D$22,MATCH(VALUE(Table32[[#This Row],[Credit_Utilization_Ratio]]),Ponderaciones!$D$19:$D$22,1),1) -> 5 | X2: =IF(Table32[[#This Row],[Num_Credit_Card]]<=2.5,5,IF(Table32[[#This Row],[Num_Credit_Card]]<=7.5,0,-5)) -> 5 | Y2: =IF(Table32[[#This Row],[Num_Bank_Accounts]]<=2.5, 5, IF(Table32[[#This Row],[Num_Bank_Accounts]]>=5.5,-5,0)) -> -5 | Z2: =IF(AND(Table32[[#This Row],[Outstanding_Debt]]>Ponderaciones!$D$18,Table32[[#This Row],[Payment_of_Min_Amount]]="Yes"),-20,0) -> 0 | AA2: =(Table32[[#This Row],[Score Delay from due date]]+Table32[[#This Row],[Score Num Delayed Payments]])*IF(Table32[[#This Row],[Class1]]="Poor",-0.5,IF(Table32[[#This Row],[Class1]]="Good",0.5,0.25)) -> 1.25 | AB2: =IF(Table32[[#This Row],[Score Delay from due date]]>10,"Good", IF(Table32[[#This Row],[Score Delay from due date]]<=-5,"Poor","Standard")) -> Standard | AC2: =ROUND((Table32[[#This Row],[Score Delay from due date]]+Table32[[#This Row],[Score Payment of Min Amount]]+Table32[[#This Row],[Score Num Delayed Payments]]+Table32[[#This Row],[Score Interest Rate]])*1.4+(Table32[[#This Row],[Score Outstanding Debt]]+Table32[[#This Row],[Score Num Loan]]+Table32[[#This Row],[Score Credit Utilization Ratio]])*1.2+(Table32[[#This Row],[Score Credit Inquiries]]+Table32[[#This Row],[Score Bank Account]]+Table32[[#This Row],[Ajustment Credit History]]+Table32[[#This Row],[Score Credit Mix]]+Table32[[#This Row],[Score Num Credit Card]])*1.1 +Table32[[#This Row],[Weigh Credit History]]+Table32[[#This Row],[Adjustment Outsanding Debt]],0) -> 30 | AD2: =IF(Table32[[#This Row],[Predicted Score]]<=5,"Poor",IF(Table32[[#This Row],[Predicted Score]]<95,"Standard","Good")) -> Standard | AE2: =+IF(Table32[[#This Row],[Credit Prediction]]<>"Poor","Accept","Reject") -> Accept | AJ2: Instrucciones de llenado del modelo Para poder introducir datos al modelo las columnas a evaluar tienen que tener el siguiente orden: Interest_Rate, Delay_from_due_date, Payment_of_Min_Amount, Outstanding_Debt, Num_Credit_Inquiries, Num_of_Delayed_Payment, Num_of_Loan, Credit_Utilization_Ratio, Num_Bank_Accounts, Num_Credit_Card, Credit_Mix, Credit_History_Age, en las primeras 12 columnas del archivo. Para las variables que no son numéricas estas son sus clasificaciones: • Payment_of_Min_Amount: Yes, No, NM o NM significa Not Mentioned • Credit_Mix: Good, Standard, Poor También es importante mencionar que el Interest_Rate se debe indicar como números enteros, no como porcentaje. Para Outstanding_Debt, Credit_Utilization_Ratio y Credit_History_Age se pueden usar puntos decimales y para las restantes son números enteros. El Delay_from_due_date debe indicarse en número de días. Los resultados se muestran del lado derecho de los datos, cada uno tiene su etiqueta para que se sepa a qué se está refiriendo. • Nota: Se ocultaron las hojas y columnas que no son necesarias para el usuario, ya que se utilizan para que el modelo pueda funcionar correctamente.
A3: 11 | B3: 23 | C3: No | D3: 0.54 | E3: 2 | F3: 3 | G3: 3 | H3: 34.02348 | I3: 2 | J3: 9 | K3: Poor | L3: 11.083333 | M3: Standard | N3: =INDEX(Ponderaciones!$C$38:$D$41,MATCH(VALUE(Table32[[#This Row],[Interest_Rate]]),Ponderaciones!$D$38:$D$41,1),1) -> 5 | O3: =INDEX(Ponderaciones!$C$5:$D$11,MATCH(Table32[[#This Row],[Delay_from_due_date]],Ponderaciones!$D$5:$D$11,1),1) -> -5 | P3: =VLOOKUP(Table32[[#This Row],[Payment_of_Min_Amount]],Ponderaciones!$C$56:$D$58,2,FALSE) -> 15 | Q3: =INDEX(Ponderaciones!$C$16:$D$18,MATCH(VALUE(Table32[[#This Row],[Outstanding_Debt]]),Ponderaciones!$D$16:$D$18,1),1) -> 10 | R3: =IF(Table32[[#This Row],[Credit_Mix]]="Good",10,IF(Table32[[#This Row],[Credit_Mix]]="Standard",5,0)) -> 0 | S3: =IF(AND(Table32[[#This Row],[Credit_History_Age]]>15,Table32[[#This Row],[Interest_Rate]]<7),5,0) -> 0 | T3: =INDEX(Ponderaciones!$C$45:$D$48,MATCH(VALUE(Table32[[#This Row],[Num_Credit_Inquiries]]),Ponderaciones!$D$45:$D$48,1),1) -> 10 | U3: =INDEX(Ponderaciones!$C$12:$D$15,MATCH(VALUE(Table32[[#This Row],[Num_of_Delayed_Payment]]),Ponderaciones!$D$12:$D$15,1),1) -> 15 | V3: =INDEX(Ponderaciones!$C$42:$D$44,MATCH(VALUE(Table32[[#This Row],[Num_of_Loan]]),Ponderaciones!$D$42:$D$44,1),1) -> 5 | W3: =INDEX(Ponderaciones!$C$19:$D$22,MATCH(VALUE(Table32[[#This Row],[Credit_Utilization_Ratio]]),Ponderaciones!$D$19:$D$22,1),1) -> 0 | X3: =IF(Table32[[#This Row],[Num_Credit_Card]]<=2.5,5,IF(Table32[[#This Row],[Num_Credit_Card]]<=7.5,0,-5)) -> -5 | Y3: =IF(Table32[[#This Row],[Num_Bank_Accounts]]<=2.5, 5, IF(Table32[[#This Row],[Num_Bank_Accounts]]>=5.5,-5,0)) -> 5 | Z3: =IF(AND(Table32[[#This Row],[Outstanding_Debt]]>Ponderaciones!$D$18,Table32[[#This Row],[Payment_of_Min_Amount]]="Yes"),-20,0) -> 0 | AA3: =(Table32[[#This Row],[Score Delay from due date]]+Table32[[#This Row],[Score Num Delayed Payments]])*IF(Table32[[#This Row],[Class1]]="Poor",-0.5,IF(Table32[[#This Row],[Class1]]="Good",0.5,0.25)) -> -5 | AB3: =IF(Table32[[#This Row],[Score Delay from due date]]>10,"Good", IF(Table32[[#This Row],[Score Delay from due date]]<=-5,"Poor","Standard")) -> Poor | AC3: =ROUND((Table32[[#This Row],[Score Delay from due date]]+Table32[[#This Row],[Score Payment of Min Amount]]+Table32[[#This Row],[Score Num Delayed Payments]]+Table32[[#This Row],[Score Interest Rate]])*1.4+(Table32[[#This Row],[Score Outstanding Debt]]+Table32[[#This Row],[Score Num Loan]]+Table32[[#This Row],[Score Credit Utilization Ratio]])*1.2+(Table32[[#This Row],[Score Credit Inquiries]]+Table32[[#This Row],[Score Bank Account]]+Table32[[#This Row],[Ajustment Credit History]]+Table32[[#This Row],[Score Credit Mix]]+Table32[[#This Row],[Score Num Credit Card]])*1.1 +Table32[[#This Row],[Weigh Credit History]]+Table32[[#This Row],[Adjustment Outsanding Debt]],0) -> 66 | AD3: =IF(Table32[[#This Row],[Predicted Score]]<=5,"Poor",IF(Table32[[#This Row],[Predicted Score]]<95,"Standard","Good")) -> Standard | AE3: =+IF(Table32[[#This Row],[Credit Prediction]]<>"Poor","Accept","Reject") -> Accept
A4: 11 | B4: 23 | C4: NM | D4: 0.54 | E4: 2 | F4: 1 | G4: 3 | H4: 28.812262 | I4: 2 | J4: 6 | K4: Standard | L4: 18.583333 | M4: Poor | N4: =INDEX(Ponderaciones!$C$38:$D$41,MATCH(VALUE(Table32[[#This Row],[Interest_Rate]]),Ponderaciones!$D$38:$D$41,1),1) -> 5 | O4: =INDEX(Ponderaciones!$C$5:$D$11,MATCH(Table32[[#This Row],[Delay_from_due_date]],Ponderaciones!$D$5:$D$11,1),1) -> -5 | P4: =VLOOKUP(Table32[[#This Row],[Payment_of_Min_Amount]],Ponderaciones!$C$56:$D$58,2,FALSE) -> -5 | Q4: =INDEX(Ponderaciones!$C$16:$D$18,MATCH(VALUE(Table32[[#This Row],[Outstanding_Debt]]),Ponderaciones!$D$16:$D$18,1),1) -> 10 | R4: =IF(Table32[[#This Row],[Credit_Mix]]="Good",10,IF(Table32[[#This Row],[Credit_Mix]]="Standard",5,0)) -> 5 | S4: =IF(AND(Table32[[#This Row],[Credit_History_Age]]>15,Table32[[#This Row],[Interest_Rate]]<7),5,0) -> 0 | T4: =INDEX(Ponderaciones!$C$45:$D$48,MATCH(VALUE(Table32[[#This Row],[Num_Credit_Inquiries]]),Ponderaciones!$D$45:$D$48,1),1) -> 10 | U4: =INDEX(Ponderaciones!$C$12:$D$15,MATCH(VALUE(Table32[[#This Row],[Num_of_Delayed_Payment]]),Ponderaciones!$D$12:$D$15,1),1) -> 15 | V4: =INDEX(Ponderaciones!$C$42:$D$44,MATCH(VALUE(Table32[[#This Row],[Num_of_Loan]]),Ponderaciones!$D$42:$D$44,1),1) -> 5 | W4: =INDEX(Ponderaciones!$C$19:$D$22,MATCH(VALUE(Table32[[#This Row],[Credit_Utilization_Ratio]]),Ponderaciones!$D$19:$D$22,1),1) -> 5 | X4: =IF(Table32[[#This Row],[Num_Credit_Card]]<=2.5,5,IF(Table32[[#This Row],[Num_Credit_Card]]<=7.5,0,-5)) -> 0 | Y4: =IF(Table32[[#This Row],[Num_Bank_Accounts]]<=2.5, 5, IF(Table32[[#This Row],[Num_Bank_Accounts]]>=5.5,-5,0)) -> 5 | Z4: =IF(AND(Table32[[#This Row],[Outstanding_Debt]]>Ponderaciones!$D$18,Table32[[#This Row],[Payment_of_Min_Amount]]="Yes"),-20,0) -> 0 | AA4: =(Table32[[#This Row],[Score Delay from due date]]+Table32[[#This Row],[Score Num Delayed Payments]])*IF(Table32[[#This Row],[Class1]]="Poor",-0.5,IF(Table32[[#This Row],[Class1]]="Good",0.5,0.25)) -> -5 | AB4: =IF(Table32[[#This Row],[Score Delay from due date]]>10,"Good", IF(Table32[[#This Row],[Score Delay from due date]]<=-5,"Poor","Standard")) -> Poor | AC4: =ROUND((Table32[[#This Row],[Score Delay from due date]]+Table32[[#This Row],[Score Payment of Min Amount]]+Table32[[#This Row],[Score Num Delayed Payments]]+Table32[[#This Row],[Score Interest Rate]])*1.4+(Table32[[#This Row],[Score Outstanding Debt]]+Table32[[#This Row],[Score Num Loan]]+Table32[[#This Row],[Score Credit Utilization Ratio]])*1.2+(Table32[[#This Row],[Score Credit Inquiries]]+Table32[[#This Row],[Score Bank Account]]+Table32[[#This Row],[Ajustment Credit History]]+Table32[[#This Row],[Score Credit Mix]]+Table32[[#This Row],[Score Num Credit Card]])*1.1 +Table32[[#This Row],[Weigh Credit History]]+Table32[[#This Row],[Adjustment Outsanding Debt]],0) -> 55 | AD4: =IF(Table32[[#This Row],[Predicted Score]]<=5,"Poor",IF(Table32[[#This Row],[Predicted Score]]<95,"Standard","Good")) -> Standard | AE4: =+IF(Table32[[#This Row],[Credit Prediction]]<>"Poor","Accept","Reject") -> Accept
AG7: ACCURACY* | AH7: Clasificación Good
AG8: 0.62327702 | AH8: Standard, Poor
AG10: Accuracy Accept/Reject*
AG11: 0.7811946
AG13: *Estos valores son de referencia

Sheet Árbol 1
A1: Decision tree for classification
A2: 1 if x4<1498.72 then node 2 elseif x4>=1498.72 then node 3 else Standard
A3: 2 if x3<2.5 then node 4 elseif x3>=2.5 then node 5 else Standard | I3: Outsanding Debt
A4: 3 if x4<2727.32 then node 6 elseif x4>=2727.32 then node 7 else Poor | I4: <1498 | L4: >1498 | N4: Standard
A5: 4 if x1<12.5 then node 8 elseif x1>=12.5 then node 9 else Standard
A6: 5 if x1<20.5 then node 10 elseif x1>=20.5 then node 11 else Standard | H6: <0.75 | I6: >0.75 | J6: Standard
A7: 6 if x1<14.5 then node 12 elseif x1>=14.5 then node 13 else Poor
A8: 7 if x1<26.5 then node 14 elseif x1>=26.5 then node 15 else Standard | G8: Si alguien tiene mucha outsanding debt, importa más el Payment of Minimum Amount
A9: 8 if x2<15.5 then node 16 elseif x2>=15.5 then node 17 else Standard | G9: Num of delayed payment aparece en nodo 16
A10: 9 if x1<20.5 then node 18 elseif x1>=20.5 then node 19 else Standard
A11: 10 if x2<35.5 then node 20 elseif x2>=35.5 then node 21 else Standard
A12: 11 if x4<1048.56 then node 22 elseif x4>=1048.56 then node 23 else Poor
A13: 12 if x4<1659.81 then node 24 elseif x4>=1659.81 then node 25 else Standard
A14: 13 if x4<2502 then node 26 elseif x4>=2502 then node 27 else Poor
A15: 14 if x4<2848.96 then node 28 elseif x4>=2848.96 then node 29 else Poor
A16: 15 if x1<33.5 then node 30 elseif x1>=33.5 then node 31 else Standard
A17: 16 if x7<12.5 then node 32 elseif x7>=12.5 then node 33 else Good
A18: 17 if x7<7.5 then node 34 elseif x7>=7.5 then node 35 else Standard
A19: 18 if x2<35.5 then node 36 elseif x2>=35.5 then node 37 else Standard
A20: 19 if x10<5901.83 then node 38 elseif x10>=5901.83 then node 39 else Poor | G20: El Mthly Inhand salary importa para aquellos con tasas de interés altas
A21: 20 if x6<8.5 then node 40 elseif x6>=8.5 then node 41 else Standard | G21: Credit utilization ratio aparece hasta el nodo 73
A22: 21 if x5<18.3384 then node 42 elseif x5>=18.3384 then node 43 else Poor
A23: 22 class = Standard
A24: 23 if x4<1464.93 then node 44 elseif x4>=1464.93 then node 45 else Poor
A25: 24 if x1<7.5 then node 46 elseif x1>=7.5 then node 47 else Poor
A26: 25 if x1<11.5 then node 48 elseif x1>=11.5 then node 49 else Standard
A27: 26 if x1<20.5 then node 50 elseif x1>=20.5 then node 51 else Poor
A28: 27 if x8<5.5 then node 52 elseif x8>=5.5 then node 53 else Poor
A29: 28 if x2<39.5 then node 54 elseif x2>=39.5 then node 55 else Standard
A30: 29 if x4<2865.15 then node 56 elseif x4>=2865.15 then node 57 else Poor
A31: 30 if x2<54.5 then node 58 elseif x2>=54.5 then node 59 else Standard
A32: 31 if x4<2825.68 then node 60 elseif x4>=2825.68 then node 61 else Poor
A33: 32 if x2<5.5 then node 62 elseif x2>=5.5 then node 63 else Good
... A2003: 2002 if x2<52.5 then node 2710 elseif x2>=52.5 then node 2711 else Stand...

Sheet Árbol 2
A1: Decision Tree
A2: |--- Delay_from_due_date <= 15.50
A3: | |--- Interest_Rate <= 12.50
A4: | | |--- Num_of_Delayed_Payment <= 15.50
A5: | | | |--- Delay_from_due_date <= 5.50 | R5: Delay_from_due_date <= 15.50
A6: | | | | |--- class: 0 | C6: GOOD | L6: Interest_Rate <= 12.50 | X6: Interest_Rate > 12.50
A7: | | | |--- Delay_from_due_date > 5.50 | H7: Num_Delayed_Payment <= 15.50 | N7: Num_Delayed_Payment > 15.50 | U7: Outstanding_Debt <= 1067.82 | AA7: Outstanding_Debt > 1067.82
A8: | | | | |--- class: 0 | C8: GOOD | G8: Delay_due_date <= 5.50 | J8: Delay_due_date >5.50 | M8: Monthly_Salary <= 2711.90 | P8: Monthly_Salary > 2711.90 | T8: Num_Delayed_Payment <= 18.50 | W8: Num_Delayed_Payment > 18.50 | AA8: Delay_due_date <= 3.50 | AD8: Delay_due_date > 3.50
A9: | | |--- Num_of_Delayed_Payment > 15.50 | G9: class: 0 | J9: class: 0 | M9: class: 0 | P9: class: 2 | T9: class: 2 | W9: class: 2 | AA9: class: 1 | AD9: class: 2
A10: | | | |--- Monthly_Inhand_Salary <= 2711.90 | G10: GOOD | J10: GOOD | M10: GOOD | P10: STANDARD | T10: STANDARD | W10: STANDARD | AA10: POOR | AD10: STANDARD
A11: | | | | |--- class: 0 | C11: GOOD
A12: | | | |--- Monthly_Inhand_Salary > 2711.90
A13: | | | | |--- class: 2 | C13: STANDARD
A14: | |--- Interest_Rate > 12.50 | R14: Delay_from_due_date > 15.50
A15: | | |--- Outstanding_Debt <= 1067.82 | L15: Interest_Rate <= 5.50 | X15: Interest_Rate > 5.50
A16: | | | |--- Num_of_Delayed_Payment <= 18.50 | H16: Monthly_Inhand_Salary <= 1648.30 | N16: Monthly_Inhand_Salary > 1648.30 | T16: Outstanding_Debt <= 964.35 | Z16: Outstanding_Debt > 964.35
A17: | | | | |--- class: 2 | C17: STANDARD | G17: Outstanding_Debt <= 331.00 | J17: Outstanding_Debt > 331.00 | M17: Monthly_Inhand_Salary <= 10634.32 | O17: Monthly_Inhand_Salary > 10634.32 | S17: Outstanding_Debt <= 955.39 | V17: Outstanding_Debt > 955.39 | Y17: Outstanding_Debt <= 1307.42 | AB17: Outstanding_Debt > 1307.42
A18: | | | |--- Num_of_Delayed_Payment > 18.50 | G18: class: 0 | J18: class: 2 | M18: class: 1 | O18: class: 2 | S18: class: 2 | V18: class: 1 | Y18: class: 2 | AB18: class: 2
A19: | | | | |--- class: 2 | C19: STANDARD | G19: GOOD | J19: STANDARD | M19: POOR | O19: STANDARD | S19: STANDARD | V19: POOR | Y19: STANDARD | AB19: STANDARD
A20: | | |--- Outstanding_Debt > 1067.82
A21: | | | |--- Delay_from_due_date <= 3.50
A22: | | | | |--- class: 1 | C22: POOR
A23: | | | |--- Delay_from_due_date > 3.50
A24: | | | | |--- class: 2 | C24: STANDARD
A25: |--- Delay_from_due_date > 15.50
A26: | |--- Interest_Rate <= 5.50
A27: | | |--- Monthly_Inhand_Salary <= 1648.30
A28: | | | |--- Outstanding_Debt <= 331.00
A29: | | | | |--- class: 0 | C29: GOOD
A30: | | | |--- Outstanding_Debt > 331.00
A31: | | | | |--- class: 2 | C31: STANDARD
A32: | | |--- Monthly_Inhand_Salary > 1648.30
A33: | | | |--- Monthly_Inhand_Salary <= 10634.32
A34: | | | | |--- class: 1 | C34: POOR
A35: | | | |--- Monthly_Inhand_Salary > 10634.32
A36: | | | | |--- class: 2 | C36: STANDARD
A37: | |--- Interest_Rate > 5.50
A38: | | |--- Outstanding_Debt <= 964.35
A39: | | | |--- Outstanding_Debt <= 955.39
A40: | | | | |--- class: 2 | C40: STANDARD
...

Sheet Árbol 3
A1: Decision tree for classification
A2: 1 if x4<1498.72 then node 2 elseif x4>=1498.72 then node 3 else Standard
A3: 2 if x3<2.5 then node 4 elseif x3>=2.5 then node 5 else Standard
A4: 3 if x4<2727.32 then node 6 elseif x4>=2727.32 then node 7 else Poor | Q4: 1 | R4: Outstanding Debt
A5: 4 if x1<12.5 then node 8 elseif x1>=12.5 then node 9 else Standard | Q5: <1498 | T5: >=1498
A6: 5 if x1<20.5 then node 10 elseif x1>=20.5 then node 11 else Standard
A7: 6 if x1<14.5 then node 12 elseif x1>=14.5 then node 13 else Poor | M7: 2 | N7: Pay of Min Amount | W7: 3 | X7: Outsanding Debt
A8: 7 if x1<26.5 then node 14 elseif x1>=26.5 then node 15 else Standard | M8: Yes | O8: No or NM | W8: <2727 | Y8: >=2727
A9: 8 if x2<15.5 then node 16 elseif x2>=15.5 then node 17 else Standard
A10: 9 if x1<20.5 then node 18 elseif x1>=20.5 then node 19 else Standard | K10: 4 | L10: Interest Rate | P10: 5 | Q10: Interest Rate | V10: 6 | W10: Interest Rate | AA10: 7 | AB10: Interest Rate
A11: 10 if x2<35.5 then node 20 elseif x2>=35.5 then node 21 else Standard | K11: <12.5 | M11: >12.5 | P11: <20.5 | R11: >20.5 | V11: <14.5 | X11: >14.5 | AA11: <26.5 | AC11: >=26.5
A12: 11 if x4<1048.56 then node 22 elseif x4>=1048.56 then node 23 else Poor
A13: 12 if x4<1659.81 then node 24 elseif x4>=1659.81 then node 25 else Standard | I13: 8 | J13: Delay Due Date | L13: 9 | M13: Interest Rate | O13: 10 | P13: Delay Due Date | R13: 11 | S13: Outsanding Debt | U13: 12 | V13: Outsanding Debt | X13: Poor | Z13: 14 | AA13: Outsanding Debt | AD13: 15 | AE13: Interest Rate
A14: 13 class = Poor | I14: <15.5 | K14: >15.5 | L14: <20.5 | N14: >20.5 | O14: <35.5 | Q14: >35.5 | R14: <1048 | T14: >1048 | V14: <1660 | W14: >=1660 | X14: 13 | Z14: <2848 | AB14: >=2848 | AD14: <33.5 | AF14: >=33.5
A15: 14 if x4<2848.96 then node 26 elseif x4>=2848.96 then node 27 else Poor | O15: Standard | Q15: Poor | R15: Standard | T15: Poor | V15: Poor | W15: Standard | Z15: Standard | AB15: Poor | AD15: Standard | AF15: Poor
A16: 15 if x1<33.5 then node 28 elseif x1>=33.5 then node 29 else Standard | H16: 16 | I16: Num of Delays | L16: 17 | M16: Num of Delays | O16: 20 | Q16: 21 | R16: 22 | T16: 23 | V16: 24 | W16: 25 | Z16: 26 | AB16: 27 | AD16: 28 | AF16: 29
A17: 16 if x7<12.5 then node 30 elseif x7>=12.5 then node 31 else Good | H17: <12.5 | J17: >12.5 | L17: <7.5 | N17: >=7.5
A18: 17 if x7<7.5 then node 32 elseif x7>=7.5 then node 33 else Standard | H18: Good | J18: Standard | L18: Poor | N18: Standard
A19: 18 if x2<35.5 then node 34 elseif x2>=35.5 then node 35 else Standard | H19: 30 | J19: 31 | L19: 32 | N19: 33
A20: 19 class = Poor
A21: 20 class = Standard
A22: 21 class = Poor | K22: 18 | L22: Num of Delays
A23: 22 class = Standard | K23: <35.5 | M23: >35.5
A24: 23 class = Poor | K24: Standard | M24: Poor | N24: Poor
A25: 24 class = Poor | K25: 34 | M25: 35 | N25: 19
A26: 25 class = Standard
A27: 26 class = Standard
A28: 27 class = Poor
A29: 28 class = Standard
A30: 29 class = Poor
A31: 30 class = Good
A32: 31 class = Standard
A33: 32 class = Poor
A34: 33 class = Standard
A35: 34 class = Standard
A36: 35 class = Poor
